Workbook

Sheet Master
C2: MATERIAL | M2: LABOUR MASTER
U3: BRAND | W3: GREEN PANEL | AB3: ACTION TESSA
B4: Sl NO | C4: Description | G4: Unit | H4: Rate ( GST) | I4: sft price | L4: Sl NO | M4: Description | N4: Unit | O4: Wages inc of PF | U4: Description | V4: SIZE | W4: sft price | X4: MRP//board | Y4: discount | Z4: SP//board | AA4: selling sft price | AB4: sft price | AC4: MRP//board with GST | AD4: discount | AE4: SP//board | AF4: selling sft price
B5: 1 | C5: MDF - 2.1mm | E5: 4 | F5: 8 | G5: Per sheet | H5: 272 | I5: =H5/32 -> 8.5 | J5: overall | L5: 1 | M5: Carpenter | N5: man-day | O5: 800 | U5: MDF -2.1mm | V5: 4 ' x 8 '' | W5: 0 | X5: 0 | Y5: 0.43 | Z5: 0 | AA5: 0 | AB5: =AC5/32 -> 10.90625 | AC5: =ROUNDUP(AF5/0.78,0) -> 349 | AD5: 0.22 | AE5: =AG5/1.18 -> 8.4745763 | AF5: =roundup(AE5*32,0) -> 272 | AG5: 10
B6: =B5+1 -> 2 | C6: MDF - 3.3mm | E6: 4 | F6: 8 | G6: Per sheet | H6: 313 | I6: =H6/32 -> 9.78125 | J6: overall | L6: 2 | M6: Helper | N6: man-day | O6: 600 | U6: MDF -3.3mm | V6: 4 ' x 8 '' | W6: 17.15 | X6: =roundup(W6*32,0) -> 549 | Y6: 0.43 | Z6: =W6*(1-Y6) -> 9.7755 | AA6: =roundup(Z6*32,0) -> 313 | AB6: =AC6/32 -> 15.6875 | AC6: =ROUNDUP(AF6/0.78,0) -> 502 | AD6: 0.22 | AE6: =AG6/1.18 -> 12.20339 | AF6: =roundup(AE6*32,0) -> 391 | AG6: 14.4
B7: =B6+1 -> 3 | C7: MDF - 5.5mm | E7: 4 | F7: 8 | G7: Per sheet | H7: 497 | I7: =H7/32 -> 15.53125 | J7: overall | L7: 3 | M7: Storage | N7: SFT | O7: 280 | U7: MDF -5.5mm | V7: 4 ' x 8 '' | W7: 27.2 | X7: =roundup(W7*32,0) -> 871 | Y7: 0.43 | Z7: =W7*(1-Y7) -> 15.504 | AA7: =roundup(Z7*32,0) -> 497 | AB7: =AC7/32 -> 24.78125 | AC7: =ROUNDUP(AF7/0.78,0) -> 793 | AD7: 0.22 | AE7: =AG7/1.18 -> 19.305085 | AF7: =roundup(AE7*32,0) -> 618 | AG7: 22.78
B8: =B7+1 -> 4 | C8: MDF - 7.5mm | E8: 4 | F8: 8 | G8: Per sheet | H8: 622 | I8: =H8/32 -> 19.4375 | J8: overall | L8: 4 | M8: Open storage | N8: SFT | O8: 250 | U8: MDF -7.5mm | V8: 4 ' x 8 '' | W8: 34.06 | X8: =roundup(W8*32,0) -> 1090 | Y8: 0.43 | Z8: =W8*(1-Y8) -> 19.4142 | AA8: =roundup(Z8*32,0) -> 622 | AB8: =AC8/32 -> 31.34375 | AC8: =ROUNDUP(AF8/0.78,0) -> 1003 | AD8: 0.22 | AE8: =AG8/1.18 -> 24.423729 | AF8: =roundup(AE8*32,0) -> 782 | AG8: 28.82
B9: =B8+1 -> 5 | C9: MDF - 11mm | E9: 4 | F9: 8 | G9: Per sheet | H9: 950 | I9: =H9/32 -> 29.6875 | J9: overall | L9: 5 | M9: Architrev -Direct | N9: RFT | O9: 130 | U9: MDF -11mm | V9: 4 ' x 8 '' | W9: 52.03 | X9: =roundup(W9*32,0) -> 1665 | Y9: 0.43 | Z9: =W9*(1-Y9) -> 29.6571 | AA9: =roundup(Z9*32,0) -> 950 | AB9: =AC9/32 -> 46.5625 | AC9: =ROUNDUP(AF9/0.78,0) -> 1490 | AD9: 0.22 | AE9: =AG9/1.18 -> 36.305085 | AF9: =roundup(AE9*32,0) -> 1162 | AG9: 42.84
B10: =B9+1 -> 6 | C10: MDF - 17mm | E10: 4 | F10: 8 | G10: Per sheet | H10: 1397 | I10: =H10/32 -> 43.65625 | J10: overall | L10: 6 | M10: Architrev -With frame | N10: RFT | O10: 160 | U10: MDF -17mm | V10: 4 ' x 8 '' | W10: 76.54 | X10: =roundup(W10*32,0) -> 2450 | Y10: 0.43 | Z10: =W10*(1-Y10) -> 43.6278 | AA10: =roundup(Z10*32,0) -> 1397 | AB10: =AC10/32 -> 68.5 | AC10: =ROUNDUP(AF10/0.78,0) -> 2192 | AD10: 0.22 | AE10: =AG10/1.18 -> 53.381356 | AF10: =roundup(AE10*32,0) -> 1709 | AG10: 62.99
B11: =B10+1 -> 7 | C11: MDF - 25mm | E11: 4 | F11: 8 | G11: Per sheet | H11: 2274 | I11: =H11/32 -> 71.0625 | J11: overall | L11: 5 | M11: PLAINING | N11: RFT | O11: 15 | U11: MDF -25mm | V11: 4 ' x 8 '' | W11: 124.66 | X11: =roundup(W11*32,0) -> 3990 | Y11: 0.43 | Z11: =W11*(1-Y11) -> 71.0562 | AA11: =roundup(Z11*32,0) -> 2274 | AB11: =AC11/32 -> 111.5 | AC11: =ROUNDUP(AF11/0.78,0) -> 3568 | AD11: 0.22 | AE11: =AG11/1.18 -> 86.966102 | AF11: =roundup(AE11*32,0) -> 2783 | AG11: 102.62
B12: =B11+1 -> 8 | C12: MDF - 30mm | E12: 4 | F12: 8 | G12: Per sheet | H12: 3165 | I12: =H12/32 -> 98.90625 | J12: overall | L12: 6 | M12: BEVELLING | N12: RFT | O12: 50 | U12: MDF -30mm | V12: 4 ' x 8 '' | W12: 173.48 | X12: =roundup(W12*32,0) -> 5552 | Y12: 0.43 | Z12: =W12*(1-Y12) -> 98.8836 | AA12: =roundup(Z12*32,0) -> 3165 | AB12: =AC12/32 -> 0 | AC12: =ROUNDUP(AF12/0.78,0) -> 0 | AD12: 0.22 | AE12: =AG12/1.18 -> 0 | AF12: =roundup(AE12*32,0) -> 0 | AG12: 0
B13: =B12+1 -> 9 | C13: HDF - 3.3mm | E13: 4 | F13: 8 | G13: Per sheet | H13: 407 | I13: =H13/32 -> 12.71875 | J13: overall | U13: HDF -3.3mm | V13: 4 ' x 8 '' | W13: 22.3 | X13: =roundup(W13*32,0) -> 714 | Y13: 0.43 | Z13: =W13*(1-Y13) -> 12.711 | AA13: =roundup(Z13*32,0) -> 407 | AB13: =AC13/32 -> 20 | AC13: =ROUNDUP(AF13/0.78,0) -> 640 | AD13: 0.22 | AE13: =AG13/1.18 -> 15.576271 | AF13: =roundup(AE13*32,0) -> 499 | AG13: 18.38
B14: =B13+1 -> 10 | C14: HDF - 5.5mm | E14: 4 | F14: 8 | G14: Per sheet | H14: 657 | I14: =H14/32 -> 20.53125 | J14: overall | U14: HDF -5.5mm | V14: 4 ' x 8 '' | W14: 36.01 | X14: =roundup(W14*32,0) -> 1153 | Y14: 0.43 | Z14: =W14*(1-Y14) -> 20.5257 | AA14: =roundup(Z14*32,0) -> 657 | AB14: =AC14/32 -> 32.1875 | AC14: =ROUNDUP(AF14/0.78,0) -> 1030 | AD14: 0.22 | AE14: =AG14/1.18 -> 25.09322 | AF14: =roundup(AE14*32,0) -> 803 | AG14: 29.61
B15: =B14+1 -> 11 | C15: HDF - 7.5mm | E15: 4 | F15: 8 | G15: Per sheet | H15: 830 | I15: =H15/32 -> 25.9375 | J15: overall | U15: HDF -7.5mm | V15: 4 ' x 8 '' | W15: 45.49 | X15: =roundup(W15*32,0) -> 1456 | Y15: 0.43 | Z15: =W15*(1-Y15) -> 25.9293 | AA15: =roundup(Z15*32,0) -> 830 | AB15: =AC15/32 -> 40.71875 | AC15: =ROUNDUP(AF15/0.78,0) -> 1303 | AD15: 0.22 | AE15: =AG15/1.18 -> 31.745763 | AF15: =roundup(AE15*32,0) -> 1016 | AG15: 37.46
B16: =B15+1 -> 12 | C16: HDF - 11mm | E16: 4 | F16: 8 | G16: Per sheet | H16: 1234 | I16: =H16/32 -> 38.5625 | J16: overall | U16: HDF -11mm | V16: 4 ' x 8 '' | W16: 67.64 | X16: =roundup(W16*32,0) -> 2165 | Y16: 0.43 | Z16: =W16*(1-Y16) -> 38.5548 | AA16: =roundup(Z16*32,0) -> 1234 | AB16: =AC16/32 -> 60.5625 | AC16: =ROUNDUP(AF16/0.78,0) -> 1938 | AD16: 0.22 | AE16: =AG16/1.18 -> 47.194915 | AF16: =roundup(AE16*32,0) -> 1511 | AG16: 55.69
B17: =B16+1 -> 13 | C17: HDF - 17mm | E17: 4 | F17: 8 | G17: Per sheet | H17: 1815 | I17: =H17/32 -> 56.71875 | J17: overall | U17: HDF -17mm | V17: 4 ' x 8 '' | W17: 99.5 | X17: =roundup(W17*32,0) -> 3184 | Y17: 0.43 | Z17: =W17*(1-Y17) -> 56.715 | AA17: =roundup(Z17*32,0) -> 1815 | AB17: =AC17/32 -> 89 | AC17: =ROUNDUP(AF17/0.78,0) -> 2848 | AD17: 0.22 | AE17: =AG17/1.18 -> 69.398305 | AF17: =roundup(AE17*32,0) -> 2221 | AG17: 81.89
B18: =B17+1 -> 14 | C18: HDF - 25mm | E18: 4 | F18: 8 | G18: Per sheet | H18: 2956 | I18: =H18/32 -> 92.375 | J18: overall | U18: HDF -25mm | V18: 4 ' x 8 '' | W18: 162.06 | X18: =roundup(W18*32,0) -> 5186 | Y18: 0.43 | Z18: =W18*(1-Y18) -> 92.3742 | AA18: =roundup(Z18*32,0) -> 2956 | AB18: =AC18/32 -> 144.96875 | AC18: =ROUNDUP(AF18/0.78,0) -> 4639 | AD18: 0.22 | AE18: =AG18/1.18 -> 113.05085 | AF18: =roundup(AE18*32,0) -> 3618 | AG18: 133.4
B19: =B18+1 -> 15 | C19: HD - HMR - 3mm | E19: 4 | F19: 8 | G19: Per sheet | H19: 501 | I19: =H19/32 -> 15.65625 | J19: overall | U19: HD-HMR -3mm | V19: 4 ' x 8 '' | W19: 27.44 | X19: =roundup(W19*32,0) -> 879 | Y19: 0.43 | Z19: =W19*(1-Y19) -> 15.6408 | AA19: =roundup(Z19*32,0) -> 501 | AB19: =AC19/32 -> 21.9375 | AC19: =ROUNDUP(AF19/0.78,0) -> 702 | AD19: 0.22 | AE19: =AG19/1.18 -> 17.076271 | AF19: =roundup(AE19*32,0) -> 547 | AG19: 20.15
B20: =B19+1 -> 16 | C20: HD - HMR - 5.5mm | E20: 4 | F20: 8 | G20: Per sheet | H20: 809 | I20: =H20/32 -> 25.28125 | J20: overall | U20: HD-HMR -5.5mm | V20: 4 ' x 8 '' | W20: 44.32 | X20: =roundup(W20*32,0) -> 1419 | Y20: 0.43 | Z20: =W20*(1-Y20) -> 25.2624 | AA20: =roundup(Z20*32,0) -> 809 | AB20: =AC20/32 -> 38.84375 | AC20: =ROUNDUP(AF20/0.78,0) -> 1243 | AD20: 0.22 | AE20: =AG20/1.18 -> 30.271186 | AF20: =roundup(AE20*32,0) -> 969 | AG20: 35.72
B21: =B20+1 -> 17 | C21: HD - HMR - 8mm | E21: 4 | F21: 8 | G21: Per sheet | H21: 1090 | I21: =H21/32 -> 34.0625 | J21: overall | U21: HD-HMR -8mm | V21: 4 ' x 8 '' | W21: 59.71 | X21: =roundup(W21*32,0) -> 1911 | Y21: 0.43 | Z21: =W21*(1-Y21) -> 34.0347 | AA21: =roundup(Z21*32,0) -> 1090 | AB21: =AC21/32 -> 52.34375 | AC21: =ROUNDUP(AF21/0.78,0) -> 1675 | AD21: 0.22 | AE21: =AG21/1.18 -> 40.805085 | AF21: =roundup(AE21*32,0) -> 1306 | AG21: 48.15
B22: =B21+1 -> 18 | C22: HD - HMR - 12mm | E22: 4 | F22: 8 | G22: Per sheet | H22: 1657 | I22: =H22/32 -> 51.78125 | J22: overall | U22: HD-HMR -12mm | V22: 4 ' x 8 '' | W22: 90.81 | X22: =roundup(W22*32,0) -> 2906 | Y22: 0.43 | Z22: =W22*(1-Y22) -> 51.7617 | AA22: =roundup(Z22*32,0) -> 1657 | AB22: =AC22/32 -> 79.625 | AC22: =ROUNDUP(AF22/0.78,0) -> 2548 | AD22: 0.22 | AE22: =AG22/1.18 -> 62.076271 | AF22: =roundup(AE22*32,0) -> 1987 | AG22: 73.25
B23: =B22+1 -> 19 | C23: HD - HMR - 16mm | E23: 4 | F23: 8 | G23: Per sheet | H23: 2104 | I23: =H23/32 -> 65.75 | J23: overall | U23: HD-HMR -16mm | V23: 4 ' x 8 '' | W23: 115.31 | X23: =roundup(W23*32,0) -> 3690 | Y23: 0.43 | Z23: =W23*(1-Y23) -> 65.7267 | AA23: =roundup(Z23*32,0) -> 2104 | AB23: =AC23/32 -> 101.03125 | AC23: =ROUNDUP(AF23/0.78,0) -> 3233 | AD23: 0.22 | AE23: =AG23/1.18 -> 78.762712 | AF23: =roundup(AE23*32,0) -> 2521 | AG23: 92.94
B24: =B23+1 -> 20 | C24: HD - HMR - 18mm | E24: 4 | F24: 8 | G24: Per sheet | H24: 2468 | I24: =H24/32 -> 77.125 | J24: overall | U24: HD-HMR -18mm | V24: 4 ' x 8 '' | W24: 135.28 | X24: =roundup(W24*32,0) -> 4329 | Y24: 0.43 | Z24: =W24*(1-Y24) -> 77.1096 | AA24: =roundup(Z24*32,0) -> 2468 | AB24: =AC24/32 -> 118.5 | AC24: =ROUNDUP(AF24/0.78,0) -> 3792 | AD24: 0.22 | AE24: =AG24/1.18 -> 92.398305 | AF24: =roundup(AE24*32,0) -> 2957 | AG24: 109.03
U25: BRAND | W25: GREEN PLY | AB25: Century
U26: Description | V26: SIZE | W26: sft price | X26: MRP//board incl gst | Y26: discount | Z26: SP//board ex GST | AA26: selling sft price | AB26: sft price | AC26: MRP//board incl gst | AD26: discount | AE26: SP//board ex GST | AF26: selling sft price
B27: =B24+1 -> 21 | C27: PLY MR - 6mm | E27: 4 | F27: 8 | G27: Per sheet | H27: 1088 | I27: =H27/(E27*F27) -> 34 | J27: overall | U27: ply MR - 6mm | V27: 4 ' x 8 '' | W27: 48 | X27: =W27*32 -> 1536 | Y27: 0.1 | Z27: =roundup(W27*(1-Y27)/1.18,0) -> 37 | AA27: =Z27*32 -> 1184 | AB27: 41 | AC27: =AB27*32 -> 1312 | AD27: 0.025 | AE27: =roundup(AB27*(1-AD27)/1.18,0) -> 34 | AF27: =AE27*32 -> 1088 | AG27: 41
B28: =B27+1 -> 22 | C28: PLY MR - 8mm | E28: 4 | F28: 8 | G28: Per sheet | H28: 1376 | I28: =H28/(E28*F28) -> 43 | J28: overall | U28: ply MR - 8mm | V28: 4 ' x 8 '' | W28: 57 | X28: =W28*32 -> 1824 | Y28: 0.1 | Z28: =roundup(W28*(1-Y28)/1.18,0) -> 44 | AA28: =Z28*32 -> 1408 | AB28: 51 | AC28: =AB28*32 -> 1632 | AD28: 0.025 | AE28: =roundup(AB28*(1-AD28)/1.18,0) -> 43 | AF28: =AE28*32 -> 1376 | AG28: 51
B29: =B28+1 -> 23 | C29: PLY MR - 12mm | E29: 4 | F29: 8 | G29: Per sheet | H29: 1568 | I29: =H29/(E29*F29) -> 49 | J29: overall | U29: ply MR - 12mm | V29: 4 ' x 8 '' | W29: 69 | X29: =W29*32 -> 2208 | Y29: 0.1 | Z29: =roundup(W29*(1-Y29)/1.18,0) -> 53 | AA29: =Z29*32 -> 1696 | AB29: 59 | AC29: =AB29*32 -> 1888 | AD29: 0.025 | AE29: =roundup(AB29*(1-AD29)/1.18,0) -> 49 | AF29: =AE29*32 -> 1568 | AG29: 59
B30: =B29+1 -> 24 | C30: PLY MR - 15mm | E30: 4 | F30: 8 | G30: Per sheet | H30: 1984 | I30: =H30/(E30*F30) -> 62 | J30: overall | U30: ply MR - 15mm | V30: 4 ' x 8 '' | X30: =W30*32 -> 0 | Y30: 0.1 | Z30: =roundup(W30*(1-Y30)/1.18,0) -> 0 | AA30: =Z30*32 -> 0 | AB30: 75 | AC30: =AB30*32 -> 2400 | AD30: 0.025 | AE30: =roundup(AB30*(1-AD30)/1.18,0) -> 62 | AF30: =AE30*32 -> 1984 | AG30: 75
B31: =B30+1 -> 25 | C31: PLY MR - 18mm | E31: 4 | F31: 8 | G31: Per sheet | H31: 2336 | I31: =H31/(E31*F31) -> 73 | J31: overall | U31: ply MR - 18mm | V31: 4 ' x 8 '' | W31: 94 | X31: =W31*32 -> 3008 | Y31: 0.1 | Z31: =roundup(W31*(1-Y31)/1.18,0) -> 72 | AA31: =Z31*32 -> 2304 | AB31: 88 | AC31: =AB31*32 -> 2816 | AD31: 0.025 | AE31: =roundup(AB31*(1-AD31)/1.18,0) -> 73 | AF31: =AE31*32 -> 2336 | AG31: 88
B32: =B31+1 -> 26 | C32: PLY MR - 25mm | E32: 4 | F32: 8 | G32: Per sheet | H32: 3200 | I32: =H32/(E32*F32) -> 100 | J32: overall | U32: ply MR - 25mm | V32: 4 ' x 8 '' | X32: =W32*32 -> 0 | Y32: 0.1 | Z32: =roundup(W32*(1-Y32)/1.18,0) -> 0 | AA32: =Z32*32 -> 0 | AB32: 0 | AC32: =AB32*32 -> 0 | AD32: 0.025 | AE32: =roundup(AB32*(1-AD32)/1.18,0) -> 0 | AF32: =AE32*32 -> 0 | AG32: 0
B33: =B32+1 -> 27 | C33: PLY BWR - 6mm | E33: 4 | F33: 8 | G33: Per sheet | H33: 1294 | I33: =H33/(E33*F33) -> 40.4375 | J33: overall | U33: ply BWR - 6mm | V33: 4 ' x 8 '' | X33: =W33*32 -> 0 | Y33: 0.1 | Z33: =roundup(W33*(1-Y33)/1.18,0) -> 0 | AA33: =Z33*32 -> 0 | AC33: =AB33*32 -> 0 | AD33: 0.025 | AE33: =roundup(AB33*(1-AD33)/1.18,0) -> 0 | AF33: =AE33*32 -> 0
B34: =B33+1 -> 28 | C34: PLY BWR - 9mm | E34: 4 | F34: 8 | G34: Per sheet | H34: 1570 | I34: =H34/(E34*F34) -> 49.0625 | J34: overall | U34: ply BWR - 9mm | V34: 4 ' x 8 '' | X34: =W34*32 -> 0 | Y34: 0.1 | Z34: =roundup(W34*(1-Y34)/1.18,0) -> 0 | AA34: =Z34*32 -> 0 | AC34: =AB34*32 -> 0 | AD34: 0.025 | AE34: =roundup(AB34*(1-AD34)/1.18,0) -> 0 | AF34: =AE34*32 -> 0
B35: =B34+1 -> 29 | C35: PLY BWR- 12mm | E35: 4 | F35: 8 | G35: Per sheet | H35: 1994 | I35: =H35/(E35*F35) -> 62.3125 | J35: overall | U35: ply BWR- 12mm | V35: 4 ' x 8 '' | X35: =W35*32 -> 0 | Y35: 0.1 | Z35: =roundup(W35*(1-Y35)/1.18,0) -> 0 | AA35: =Z35*32 -> 0 | AC35: =AB35*32 -> 0 | AD35: 0.025 | AE35: =roundup(AB35*(1-AD35)/1.18,0) -> 0 | AF35: =AE35*32 -> 0
B36: =B35+1 -> 30 | C36: PLY BWR- 16mm | E36: 4 | F36: 8 | G36: Per sheet | H36: 2520 | I36: =H36/(E36*F36) -> 78.75 | J36: overall | U36: ply BWR- 16mm | V36: 4 ' x 8 '' | X36: =W36*32 -> 0 | Y36: 0.1 | Z36: =roundup(W36*(1-Y36)/1.18,0) -> 0 | AA36: =Z36*32 -> 0 | AC36: =AB36*32 -> 0 | AD36: 0.025 | AE36: =roundup(AB36*(1-AD36)/1.18,0) -> 0 | AF36: =AE36*32 -> 0
B37: =B36+1 -> 31 | C37: PLY BWR- 19mm | E37: 4 | F37: 8 | G37: Per sheet | H37: 2907 | I37: =H37/(E37*F37) -> 90.84375 | J37: overall | U37: ply BWR- 19mm | V37: 4 ' x 8 '' | X37: =W37*32 -> 0 | Y37: 0.1 | Z37: =roundup(W37*(1-Y37)/1.18,0) -> 0 | AA37: =Z37*32 -> 0 | AC37: =AB37*32 -> 0 | AD37: 0.025 | AE37: =roundup(AB37*(1-AD37)/1.18,0) -> 0 | AF37: =AE37*32 -> 0
B38: =B37+1 -> 32 | C38: PLY BWP - 6mm | E38: 4 | F38: 8 | G38: Per sheet | H38: 1344 | I38: =H38/(E38*F38) -> 42 | J38: overall | U38: ply BWP - 6mm | V38: 4 ' x 8 '' | W38: 62 | X38: =W38*32 -> 1984 | Y38: 0.1 | Z38: =roundup(W38*(1-Y38)/1.18,0) -> 48 | AA38: =Z38*32 -> 1536 | AB38: 50 | AC38: =AB38*32 -> 1600 | AD38: 0.025 | AE38: =roundup(AB38*(1-AD38)/1.18,0) -> 42 | AF38: =AE38*32 -> 1344
B39: =B38+1 -> 33 | C39: PLY BWP - 9mm | E39: 4 | F39: 8 | G39: Per sheet | H39: 1632 | I39: =H39/(E39*F39) -> 51 | J39: overall | U39: ply BWP - 9mm | V39: 4 ' x 8 '' | W39: 74 | X39: =W39*32 -> 2368 | Y39: 0.1 | Z39: =roundup(W39*(1-Y39)/1.18,0) -> 57 | AA39: =Z39*32 -> 1824 | AB39: 61 | AC39: =AB39*32 -> 1952 | AD39: 0.025 | AE39: =roundup(AB39*(1-AD39)/1.18,0) -> 51 | AF39: =AE39*32 -> 1632
B40: =B39+1 -> 34 | C40: PLY BWP - 12mm | E40: 4 | F40: 8 | G40: Per sheet | H40: 2016 | I40: =H40/(E40*F40) -> 63 | J40: overall | U40: ply BWP - 12mm | V40: 4 ' x 8 '' | W40: 87 | X40: =W40*32 -> 2784 | Y40: 0.1 | Z40: =roundup(W40*(1-Y40)/1.18,0) -> 67 | AA40: =Z40*32 -> 2144 | AB40: 76 | AC40: =AB40*32 -> 2432 | AD40: 0.025 | AE40: =roundup(AB40*(1-AD40)/1.18,0) -> 63 | AF40: =AE40*32 -> 2016
B41: =B40+1 -> 35 | C41: PLY BWP - 16mm | E41: 4 | F41: 8 | G41: Per sheet | H41: 2560 | I41: =H41/(E41*F41) -> 80 | J41: overall | U41: ply BWP - 16mm | V41: 4 ' x 8 '' | X41: =W41*32 -> 0 | Y41: 0.1 | Z41: =roundup(W41*(1-Y41)/1.18,0) -> 0 | AA41: =Z41*32 -> 0 | AB41: 96 | AC41: =AB41*32 -> 3072 | AD41: 0.025 | AE41: =roundup(AB41*(1-AD41)/1.18,0) -> 80 | AF41: =AE41*32 -> 2560
...

Sheet STORAGE -  SHUTTER 
B2: STORAGE - SHUTTER
B3: Nos(cove) | C3: 1 | F3: Shelves (horizontal) | H3: 0 | K3: wall cabinet- 700X600X300MM
B4: Length ( Meters) | C4: 0.6 | D4: M | F4: Partition (vertical) | H4: 0
B5: Height (Meters) | C5: 0.2 | D5: M | F5: Shutters | H5: 0
B6: Depth (Meters) | C6: 0.45 | D6: M | F6: Internal drawers | H6: 1
B7: Base Material | C7: PLY MR - 18mm | D7: SFT | F7: 0.6 | G7: 1.8 | H7: 0.43
B8: Secondary Material | C8: MDF - 5.5mm | F8: Additional
B9: Internal Finish | C9: 0.8mm Off white laminate | F9: Jaali-6mm MDF+DUCO
B10: External Finish | C10: SF Laminate
B11: Hinges | C11: Hettich -Soft | F11: Area(SFT) | H11: =roundup(C4*C5*10.764,0) -> 2
B12: Drawer Channel | C12: EBCO - 300mm-Normal | F12: Rate/Sft. | H12: =H44 -> #N/A
B13: Low Value | C13: Yes | F13: Amount | H13: =G44 -> #N/A
H14: 8
B15: Actual Material usage post wastage | F15: Absolute Pending material post wastage
B16: SFT | C16: NOs | F16: SFT | H16: NOs
A17: Base Material | B17: =O71 -> 53.850139 | C17: =P71 -> 1.6828169 | F17: =H17*32 -> 32 | H17: =1-I15 -> 1
A18: Secondary Material | B18: =O72 -> 4.4756712 | C18: =P72 -> 0.13986472 | F18: =H18*32 -> 32 | H18: =1-I16 -> 1
A19: Internal Finish | B19: =IF(or(C9=Master!C61,C9=Master!C62),O74,O73) -> 93.918053 | C19: =P73 -> 2.9349391 | F19: =H19*32 -> 32 | H19: =1-I17 -> 1 | L19: MATERIAL CALCULATION
A20: External Finish | B20: =IF(or(C10=Master!C61,C10=Master!C62),O76,O75) -> 22.733568 | C20: =P75 -> 0.710424 | L20: Area | M20: =upper(M23) -> NOS | N20: LENGTH | O20: HEIGHT | P20: DEPTH | R20: =upper(L29) -> SHELVES | S20: PARTITION | T20: DRAWERS | U20: SHUTTERS
M21: =$C$3 -> 1 | N21: =C4 -> 0.6 | O21: =C5 -> 0.2 | P21: =C6 -> 0.45 | R21: =H3 -> 0 | S21: =H4 -> 0 | T21: =H6 -> 1 | U21: =H5 -> 0
A22: BILL OF MATERIALS (Per Unit) | S22: =F7 -> 0.6 | T22: =G7 -> 1.8 | U22: =H7 -> 0.43
A23: Sl NO | B23: CATEGORY | C23: ITEM | D23: UOM | E23: QUANTITY | F23: RATE | G23: AMOUNT | I23: SFT | J23: NOs | M23: Nos | N23: L | O23: H | P23: D | Q23: Quantity | R23: BM | S23: SM
A24: 1 | B24: Base Material | C24: =C7 -> PLY MR - 18mm | D24: NOS | E24: =C17 -> 1.6828169 | F24: =vlookup(C24,Master!$C$5:$H$110,6,0) -> 2336 | G24: =F24*E24 -> 3931.0602 | I24: =O71 -> 53.850139 | J24: =I24/32 -> 1.6828169 | L24: BASE MATERIAL
A25: =A24+1 -> 2 | B25: Secondary Material | C25: Blockboard -19mm | D25: NOS | E25: =C18 -> 0.13986472 | F25: =vlookup(C25,Master!$C$5:$H$110,6,0) -> 3450 | G25: =F25*E25 -> 482.5333 | I25: =O72 -> 4.4756712 | J25: =I25/32 -> 0.13986472 | L25: Front/Shutter&Back | M25: =$M$21*2 -> 2 | N25: =$N$21 -> 0.6 | O25: =$O$21 -> 0.2 | P25: 0 | Q25: =M25*N25*O25 -> 0.24 | R25: =$Q$25/2 -> 0.12 | S25: =$Q$25/2 -> 0.12
A26: =A25+1 -> 3 | B26: Internal Finish | C26: =C9 -> 0.8mm Off white laminate | D26: NOS | E26: =IF(or(C9=Master!C61,C9=Master!C62),B19,C19) -> 2.9349391 | F26: =vlookup(C26,Master!$C$5:$H$110,6,0) -> 750 | G26: =F26*E26 -> 2201.2044 | I26: =O73 -> 93.918053 | J26: =I26/32 -> 2.9349391 | L26: Sides | M26: =$M$21*2 -> 2 | N26: 0 | O26: =O21 -> 0.2 | P26: =$P$21 -> 0.45 | Q26: =M26*O26*P26 -> 0.18 | R26: =Q26 -> 0.18 | S26: 0
A27: =A26+1 -> 4 | B27: internal Polish " | C27: =if(or(C26=Master!C57,C26=Master!C58),Master!C67,"NA") -> NA | D27: NOS | E27: =O74 -> 85.380048 | F27: =ifna(vlookup(C27,Master!$C$5:$H$110,6,0),"") | G27: =F27*E27 -> 0 | L27: Top/Bottom | M27: =$M$21*2 -> 2 | N27: =$N$21 -> 0.6 | O27: 0 | P27: =$P$21 -> 0.45 | Q27: =M27*N27*P27 -> 0.54 | R27: =Q27 -> 0.54 | S27: 0
A28: =A27+1 -> 5 | B28: External Finish | C28: =C10 -> SF Laminate | D28: NOS | E28: =IF(or(C10=Master!C61,C10=Master!C62),B20,C20) -> 0.710424 | F28: =vlookup(C28,Master!$C$5:$H$110,6,0) -> 1500 | G28: =F28*E28 -> 1065.636 | L28: Partition | M28: =$S$21 -> 0 | N28: 0 | O28: =$O$21 -> 0.2 | P28: =$P$21 -> 0.45 | Q28: =M28*O28*P28 -> 0 | R28: =Q28 -> 0 | S28: 0 | AB28: BILL OF MATERIALS (Per Unit)
A29: =A28+1 -> 6 | B29: External Polish | C29: =if(or(C28=Master!C72,C28=Master!C73),Master!C82,"NA") -> NA | D29: NOS | E29: =O76 -> 21 | F29: =ifna(vlookup(C29,Master!$C$5:$H$110,6,0),"") | G29: =F29*E29 -> 0 | L29: shelves | M29: =$R$21 -> 0 | N29: =$N$21 -> 0.6 | O29: 0 | P29: =$P$21 -> 0.45 | Q29: =M29*N29*P29 -> 0 | R29: =Q29 -> 0 | S29: 0
A30: =A29+1 -> 7 | B30: Adhessive | C30: Fevicol (SH+SR) | D30: KG | E30: =E25 -> 0.13986472 | F30: =vlookup(C30,Master!$C$5:$H$110,6,0) -> 245 | G30: =F30*E30 -> 34.266858 | L30: Drawers | M30: =T21 -> 1 | N30: =S22 -> 0.6 | O30: =T22 -> 1.8 | P30: =U22 -> 0.43
A31: =A30+1 -> 8 | B31: Handle /Knob | C31: Handle | D31: NOS | E31: =H5+H6 -> 1 | F31: =vlookup(C31,Master!$C$5:$H$110,6,0) -> 200 | G31: =F31*E31 -> 200 | L31: Base | M31: =T21 -> 1 | N31: =$N$30 -> 0.6 | O31: 0 | P31: =$P$30 -> 0.43 | Q31: =M31*N31*P31 -> 0.258 | R31: 0 | S31: =Q31 -> 0.258
A32: =A31+1 -> 9 | B32: Hinges | C32: Hettich -Soft | D32: PAIRS | E32: =H5 -> 0 | F32: =vlookup(C32,Master!$C$5:$H$110,6,0) -> 330 | G32: =F32*E32 -> 0 | L32: Sides(R/L) | M32: =T21*2 -> 2 | N32: 0 | O32: =$O$30 -> 1.8 | P32: =$P$30 -> 0.43 | Q32: =M32*O32*P32 -> 1.548 | R32: =Q32 -> 1.548 | S32: 0
A33: =A32+1 -> 10 | B33: Channels for drawers | C33: EBCO - 200mm-Normal | D33: PAIRS | E33: =H6 -> 1 | F33: =VLOOKUP(C33,Master!$D$5:$H$125,5,0) -> #N/A | G33: =F33*E33 -> #N/A | L33: Sides(F/B) | M33: =T21*2 -> 2 | N33: =$N$30 -> 0.6 | O33: =$O$30 -> 1.8 | P33: 0 | Q33: =M33*N33*O33 -> 2.16 | R33: =Q33 -> 2.16 | S33: 0
A34: =A33+1 -> 11 | B34: lock | C34: Epco Locks | D34: NOS | E34: 0 | F34: =vlookup(C34,Master!$C$5:$H$110,6,0) -> 174 | G34: =F34*E34 -> 0 | O34: Total(SQM) | Q34: =SUM(Q25:Q33) -> 4.926 | R34: =SUM(R25:R33) -> 4.548 | S34: =SUM(S25:S33) -> 0.378
A35: =A34+1 -> 12 | B35: Nails | C35: Nails | D35: KG | E35: =H11*0.15 -> 0.3 | F35: =vlookup(C35,Master!$C$5:$H$110,6,0) -> 80 | G35: =F35*E35 -> 24 | O35: Total(SFT) | Q35: =Q34*10.764 -> 53.023464 | R35: =R34*10.764 -> 48.954672 | S35: =S34*10.764 -> 4.068792
A36: =A35+1 -> 13 | B36: jaali | C36: Jaali-18mm MDF+DUCO | D36: SFT | E36: 0 | F36: =VLOOKUP(C36,Master!C68:H81,6,0) -> 880 | G36: =F36*E36 -> 0
A37: =A36+1 -> 14 | B37: Additional | C37: Melamine | D37: SFT | E37: 0 | F37: =VLOOKUP(C37,Master!$C$5:$H$144,6,0) -> 120 | G37: =(ifs(E37=0,0,E37>=1,(E37*F37))) -> 0 | L37: FINISHING MATERIAL
A38: =A37+1 -> 15 | C38: 5mm Mirror | D38: SFT | E38: 0 | F38: =VLOOKUP(C38,Master!$C$5:$H$144,6,0) -> 150 | G38: =F38*E38 -> 0 | L38: INTERNAL FINISH
A39: =A38+1 -> 16 | B39: Miscellaneous item | C39: 0.025 | D39: LS | E39: 1 | F39: =(sum(G24:G38)*C39) -> #N/A | G39: =F39*E39 -> #N/A | L39: Front/Shutter &Back | M39: =$M$21*3 -> 3 | N39: =$N$21 -> 0.6 | O39: =$O$21 -> 0.2 | P39: 0 | Q39: =M39*N39*O39 -> 0.36
A40: =A39+1 -> 17 | B40: Labour | C40: Storage | D40: SFT | E40: =H11 -> 2 | F40: =VLOOKUP(C40,Master!M5:O12,3,0) -> 280 | G40: =F40*E40 -> 560 | L40: Sides | M40: =$M$21*2 -> 2 | N40: 0 | O40: =$O$21 -> 0.2 | P40: =$P$21 -> 0.45 | Q40: =M40*O40*P40 -> 0.18
A41: =A40+1 -> 18 | B41: Transportation | F41: 0.025 | G41: =SUM(G24:G40)*F41 -> #N/A | L41: Top/Bottom | M41: =$M$21*2 -> 2 | N41: =$N$21 -> 0.6 | O41: 0 | P41: =$P$21 -> 0.45 | Q41: =M41*N41*P41 -> 0.54
...

Sheet  STORAGE  - OPEN  
B2: STORAGE - OPEN
B3: Nos(cove) | C3: 1 | F3: Shelves (horizontal) | H3: 5 | K3: Open unit- 500X600X300MM
B4: Length ( Meters) | C4: 0.75 | D4: M | F4: Partition (vertical) | H4: 2
B5: Height (Meters) | C5: 1.5 | D5: M
B6: Depth (Meters) | C6: 0.45 | D6: M | F6: Area(SFT) | H6: =ROUNDUP(C4*C5*10.764,0) -> 13
B7: Base Material | C7: MDF - 17mm | F7: Rate/Sft. | H7: =H34 -> 1778.8751
B8: Secondary Material | C8: MDF - 17mm | F8: Amount | H8: =G34 -> 23125.376
B9: Finish | C9: HGL Laminate
B10: Low Value | C10: Yes
B12: Actual Material usage post wastage | F12: Absolute Pending material post wastage
B13: SFT | C13: NOs | F13: SFT | H13: NOs
A14: Base Material | B14: =O46 -> 59.942025 | C14: =Q46 -> 1.8731883 | F14: =H14*32 -> 32 | H14: =1-I12 -> 1
A15: Secondary Material | B15: =O47 -> 13.32045 | C15: =Q47 -> 0.41626406 | F15: =H15*32 -> 32 | H15: =1-I13 -> 1
A16: Finish | B16: =IF(or(C9=Master!C61,C9=Master!C62),O49,O48) -> 146.52495 | C16: =IF(or(C9=Master!C61,C9=Master!C62),O49,Q48) -> 4.5789047 | F16: =H16*32 -> 32 | H16: =1-I14 -> 1
L17: MATERIAL CALCULATION
L18: Area | M18: =upper(M20) -> NOS | N18: LENGTH | O18: HEIGHT | P18: DEPTH | R18: =upper(L26) -> SHELVES | S18: PARTITION
A19: BILL OF MATERIALS (Per Unit) | L19: =H6 -> 13 | M19: =$C$3 -> 1 | N19: =C4 -> 0.75 | O19: =C5 -> 1.5 | P19: =C6 -> 0.45 | R19: =H3 -> 5 | S19: =H4 -> 2
A20: Sl NO | B20: CATEGORY | C20: ITEM | D20: UOM | E20: QUANTITY | F20: RATE | G20: AMOUNT | I20: SFT | J20: NOs | M20: Nos | N20: L | O20: H | P20: D | Q20: Quantity | R20: BM | S20: SM
A21: 1 | B21: BASE MATERIAL | C21: ply MR - 12mm | D21: NOS | E21: =ROUNDUP(J21,0) -> 3 | F21: =vlookup(C21,Master!$C$5:$H$110,6,0) -> 1568 | G21: =F21*E21 -> 4704 | I21: =Q28*1.1 -> 73.262475 | J21: =I21/32 -> 2.2894523 | L21: BASE MATERIAL
A22: 2 | B22: Secondary Material | C22: Flexiply - 8mm | D22: NOS | E22: =C15 -> 0.41626406 | F22: =vlookup(C22,Master!$C$5:$H$110,6,0) -> 2496 | G22: =F22*E22 -> 1038.9951 | I22: =Q39*1.1 -> 146.52495 | J22: =I22/32 -> 4.5789047 | L22: Back | M22: =$M$19 -> 1 | N22: =$N$19 -> 0.75 | O22: =$O$19 -> 1.5 | P22: 0 | Q22: =M22*N22*O22 -> 1.125 | R22: - | S22: =Q22 -> 1.125
A23: 3 | B23: Finish | C23: =C9 -> HGL Laminate | D23: NOS | E23: =IF(or(C6=Master!C58,C6=Master!C59),B16,C16) -> 4.5789047 | F23: =vlookup(C23,Master!$C$5:$H$110,6,0) -> 1830 | G23: =F23*E23 -> 8379.3956 | L23: Sides | M23: =$M$19*2 -> 2 | N23: 0 | O23: =O19 -> 1.5 | P23: =$P$19 -> 0.45 | Q23: =M23*O23*P23 -> 1.35 | R23: =Q23 -> 1.35 | S23: 0
A24: 2 | B24: internal Polish " | C24: =if(or(C23=Master!C57,C23=Master!C58),Master!C67,"NA") -> NA | D24: NOS | E24: =N49 -> 133.2045 | F24: =ifna(vlookup(C24,Master!$C$5:$H$110,6,0),"") | G24: =F24*E24 -> 0 | L24: Top/Bottom | M24: =$M$19*2 -> 2 | N24: =$N$19 -> 0.75 | O24: 0 | P24: =$P$19 -> 0.45 | Q24: =M24*N24*P24 -> 0.675 | R24: =Q24 -> 0.675 | S24: 0
A25: 3 | B25: Fevicol (SH+SR) | D25: KG | E25: =E21 -> 3 | F25: 250 | G25: =F25*E25 -> 750 | L25: Partition | M25: =$S$19 -> 2 | N25: 0 | O25: =$O$19 -> 1.5 | P25: =$P$19 -> 0.45 | Q25: =M25*O25*P25 -> 1.35 | R25: =Q25 -> 1.35 | S25: 0 | AB25: BILL OF MATERIALS (Per Unit)
A26: 4 | B26: Nails | C26: Nails | D26: KG | E26: =H6*0.15 -> 1.95 | F26: =vlookup(C26,Master!$C$5:$H$110,6,0) -> 80 | G26: =F26*E26 -> 156 | L26: shelves | M26: =$R$19 -> 5 | N26: =$N$19 -> 0.75 | O26: 0 | P26: =$P$19 -> 0.45 | Q26: =M26*N26*P26 -> 1.6875 | R26: =Q26 -> 1.6875 | S26: 0
A27: 5 | B27: jaali | C27: Jaali-18mm MDF+DUCO | D27: SFT | E27: 0 | F27: =vlookup(C27,Master!$C$5:$H$110,6,0) -> 880 | G27: =F27*E27 -> 0 | O27: Total(Sqm) | Q27: =SUM(Q22:Q26) -> 6.1875 | R27: =SUM(R22:R26) -> 5.0625 | S27: =SUM(S22:S26) -> 1.125
A28: 6 | B28: Additional | C28: Melamine | D28: SFT | E28: 0 | F28: =VLOOKUP(C28,Master!$C$5:$H$144,6,0) -> 120 | G28: =(ifs(E28=0,0,E28>=1,(E28*F28))) -> 0 | O28: Total(SFT) | Q28: =Q27*10.764 -> 66.60225 | R28: =R27*10.764 -> 54.49275 | S28: =S27*10.764 -> 12.1095
A29: 7 | C29: 5mm Clear Glass | D29: SFT | E29: 0 | F29: =VLOOKUP(C29,Master!$C$5:$H$144,6,0) -> 93 | G29: =F29*E29 -> 0
A30: 8 | B30: Miscellaneous item | C30: 0.025 | D30: LS | E30: 1 | F30: =(sum(G21:G24)*C30) -> 353.05977 | G30: =F30*E30 -> 353.05977
A31: 9 | B31: Labour | C31: storage | D31: SFT | E31: =H6 -> 13 | F31: 290 | G31: =F31*E31 -> 3770 | L31: FINISHING MATERIAL
A32: 10 | B32: Transportation | F32: 0.05 | G32: =SUM(G21:G31)*F32 -> 957.57252
A33: Total (COGS) | G33: =SUM(G14:G32) -> 20109.023 | H33: =G33/$H$6 -> 1546.8479 | I33: /sft | L33: Back | M33: =$M$19*2 -> 2 | N33: =$N$19 -> 0.75 | O33: =$O$19 -> 1.5 | P33: 0 | Q33: =M33*N33*O33 -> 2.25
A34: Vendor Price | F34: 0.15 | G34: =G33+G33*F34 -> 23125.376 | H34: =G34/$H$6 -> 1778.8751 | I34: /sft | L34: Sides | M34: =$M$19*4 -> 4 | N34: 0 | O34: =$O$19 -> 1.5 | P34: =$P$19 -> 0.45 | Q34: =M34*O34*P34 -> 2.7
A35: HL Price price | F35: 0.4 | G35: =ROUNDUP(G34/(1-F35),0) -> 38543 | H35: =G35/$H$6 -> 2964.8462 | I35: /sft | L35: Top/Bottom | M35: =$M$19*4 -> 4 | N35: =$N$19 -> 0.75 | O35: 0 | P35: =$P$19 -> 0.45 | Q35: =M35*N35*P35 -> 1.35
L36: Partition | M36: =S19*2 -> 4 | N36: 0 | O36: =$O$19 -> 1.5 | P36: =$P$19 -> 0.45 | Q36: =M36*O36*P36 -> 2.7
L37: shelves | M37: =R19*2 -> 10 | N37: =$N$19 -> 0.75 | O37: 0 | P37: =$P$19 -> 0.45 | Q37: =M37*N37*P37 -> 3.375
Q38: =SUM(Q33:Q37) -> 12.375 | R38: SQM
O39: Total | Q39: =Q38*10.764 -> 133.2045 | R39: SFT
L45: Material | N45: Area (Sft) | O45: Area (inc 10% wastage) | P45: Panel (nos) | Q45: Panel (optimized)
L46: Base Material | N46: =R28 -> 54.49275 | O46: =N46*1.1 -> 59.942025 | P46: =O46/32 -> 1.8731883 | Q46: =if($C$13="Yes",ceiling(P46,1),P46) -> 1.8731883
L47: Secondary Material | N47: =S28 -> 12.1095 | O47: =N47*1.1 -> 13.32045 | P47: =O47/32 -> 0.41626406 | Q47: =if($C$13="Yes",ceiling(P47,1),P47) -> 0.41626406
...

Sheet VANITY -old
B2: NOs | C2: 1 | F2: SHELVES
B3: LENGTH | C3: 1 | D3: M | F3: PARTITION | H3: 1
B4: HEIGHT | C4: 1.2 | D4: M | F4: SHUTTERS | H4: 1
B5: DEPTH | C5: 1.3 | D5: M | F5: DRAWERS | H5: 1
B6: AREA | C6: =ROUNDUP((C2*C3*C4*10.764),0) -> 13 | D6: SFT | F6: 6 | G6: 0.5 | H6: 0.6
A8: BILL OF MATERIALS (Per Unit) | L8: MATERIAL CALCULATION
L9: Area | M9: =upper(M12) -> NOS | N9: LENGTH | O9: HEIGHT | P9: DEPTH | R9: =upper(L18) -> SHELVES | S9: PARTITION | T9: DRAWERS | U9: SHUTTERS
L10: =C6 -> 13 | M10: =$C$2 -> 1 | N10: =C3 -> 1 | O10: =C4 -> 1.2 | P10: =C5 -> 1.3 | R10: =H2 | S10: =H3 -> 1 | T10: =H5 -> 1 | U10: =H4 -> 1
S11: =F6 -> 6 | T11: =G6 -> 0.5 | U11: =H6 -> 0.6
A12: Sl NO | B12: CATEGORY | C12: ITEM | D12: UOM | E12: QUANTITY | F12: RATE | G12: AMOUNT | M12: Nos | N12: L | O12: H | P12: D | Q12: Quantity
A13: 1 | B13: BASE MATERIAL | C13: ply BWR - 18mm | D13: NOS | E13: =roundup(#REF!/32,0) -> #REF! | F13: =vlookup(C13,Master!$C$5:$H$110,6,0) -> #N/A | G13: =F13*E13 -> #N/A | L13: BASE MATERIAL
A14: 2 | B14: INTERNAL FINISH | C14: 0.8mm white | D14: NOS | E14: =roundup(#REF!/32,0) -> #REF! | F14: =vlookup(C14,Master!$C$5:$H$110,6,0) -> #N/A | G14: =F14*E14 -> #N/A | L14: Front/Shutter &Back | M14: =$M$10*2 -> 2 | N14: =$N$10 -> 1 | O14: =$O$10 -> 1.2 | P14: 0 | Q14: =M14*N14*O14 -> 2.4 | T14: B M | U14: =Q24*1.1 -> 235.38715
A15: 3 | B15: External FINISH | C15: Sf laminate | D15: NOS | E15: =roundup(#REF!/32,0) -> #REF! | F15: =vlookup(C15,Master!$C$5:$H$110,6,0) -> 1500 | G15: =F15*E15 -> #REF! | L15: Sides | M15: =$M$10*2 -> 2 | N15: 0 | O15: =O10 -> 1.2 | P15: =$P$10 -> 1.3 | Q15: =M15*O15*P15 -> 3.12 | T15: I F | U15: =Q38*1.1 -> 339.10906
A16: 4 | B16: Fevicol (SH+SR) | C16: Fevicol (SH+SR) | D16: KG | E16: =E13 -> #REF! | F16: =vlookup(C16,Master!$C$5:$H$110,6,0) -> 245 | G16: =F16*E16 -> #REF! | L16: Top/Bottom | M16: =$M$10*2 -> 2 | N16: =$N$10 -> 1 | O16: 0 | P16: =$P$10 -> 1.3 | Q16: =M16*N16*P16 -> 2.6 | T16: E F | U16: =Q50*1.1 -> 131.66525
A17: 5 | B17: Handle /Knob | C17: Handle | D17: NOS | E17: =#REF! -> #REF! | F17: =vlookup(C17,Master!$C$5:$H$110,6,0) -> 200 | G17: =F17*E17 -> #REF! | L17: Partition | M17: =$S$10 -> 1 | N17: 0 | O17: =$O$10 -> 1.2 | P17: =$P$10 -> 1.3 | Q17: =M17*O17*P17 -> 1.56 | AB17: BILL OF MATERIALS (Per Unit)
A18: 6 | B18: Hinges | C18: Ebco-Soft | D18: PAIRS | E18: =#REF! -> #REF! | F18: =vlookup(C18,Master!$C$5:$H$110,6,0) -> 180 | G18: =F18*E18 -> #REF! | L18: shelves | M18: =$R$10 | N18: =$N$10 -> 1 | O18: 0 | P18: =$P$10 -> 1.3 | Q18: =M18*N18*P18 -> 0
A19: 7 | B19: Channels for drawers | C19: Hetich -Soft | D19: PAIRS | E19: =#REF! -> #REF! | F19: =vlookup(C19,Master!$C$5:$H$110,6,0) -> #N/A | G19: =F19*E19 -> #N/A | L19: Drawers | M19: =T10 -> 1 | N19: =S11 -> 6 | O19: =T11 -> 0.5 | P19: =U11 -> 0.6
A20: 8 | B20: lock | C20: Epco Locks | D20: NOS | E20: 0 | F20: =vlookup(C20,Master!$C$5:$H$110,6,0) -> 174 | G20: =F20*E20 -> 0 | L20: Base | M20: =T10 -> 1 | N20: =$N$19 -> 6 | O20: 0 | P20: =$P$19 -> 0.6 | Q20: =M20*N20*P20 -> 3.6
A21: 9 | B21: Nails | C21: Nails | D21: KG | E21: =#REF!*0.15 -> #REF! | F21: =vlookup(C21,Master!$C$5:$H$110,6,0) -> 80 | G21: =F21*E21 -> #REF! | L21: Sides | M21: =T10*2 -> 2 | N21: 0 | O21: =$O$19 -> 0.5 | P21: =$P$19 -> 0.6 | Q21: =M21*O21*P21 -> 0.6
A22: 10 | B22: jaali | C22: Jaali(12mm MDF ) | D22: SFT | E22: 0 | F22: =vlookup(C22,Master!$C$5:$H$110,6,0) -> #N/A | G22: =F22*E22 -> #N/A | L22: Sides (F/B) | M22: =T10*2 -> 2 | N22: =$N$19 -> 6 | O22: =$O$19 -> 0.5 | P22: 0 | Q22: =M22*N22*O22 -> 6
A23: 11 | B23: Additional | C23: 8mm Clear Glass | D23: SFT | E23: 0 | F23: =vlookup(C23,#REF!,6) -> #REF! | G23: =(ifs(E23=0,0,E23>=1,(E23*F23))) -> 0 | Q23: =SUM(Q14:Q22) -> 19.88 | R23: SQM
A24: 12 | C24: Mirror | D24: SFT | E24: 0 | F24: =vlookup(C24,#REF!,6) -> #REF! | G24: =F24*E24 -> #REF! | O24: Total | Q24: =Q23*10.764 -> 213.98832 | R24: SFT
A25: 13 | C25: 8mm Extra Clear Glass | D25: SFT | E25: 0 | F25: =vlookup(C25,#REF!,6) -> #REF! | G25: =F25*E25 -> #REF!
A26: 14 | B26: Miscellaneous item | C26: 0.025 | D26: LS | E26: 1 | F26: =(sum(G13:G15)*C26) -> #N/A | G26: =F26*E26 -> #N/A | L26: FINISHING MATERIAL
A27: 15 | B27: Labour | C27: storage | D27: SFT | E27: =#REF! -> #REF! | F27: =vlookup(C27,#REF!,5,0) -> #REF! | G27: =F27*E27 -> #REF! | L27: INTERNAL FINISH
A28: 16 | B28: Transportation | F28: 0.05 | G28: =SUM(G13:G27)*F28 -> #N/A | L28: Front/Shutter &Back | M28: =$M$10*2 -> 2 | N28: =$N$10 -> 1 | O28: =$O$10 -> 1.2 | P28: 0 | Q28: =M28*N28*O28 -> 2.4
B29: Total (COGS) | G29: =SUM(G13:G28) -> #N/A | H29: =G29/$L$10 -> #N/A | I29: /sft | L29: Sides | M29: =$M$10*2 -> 2 | N29: 0 | O29: =$O$10 -> 1.2 | P29: =$P$10 -> 1.3 | Q29: =M29*O29*P29 -> 3.12
B30: GRAND TOTAL | F30: 0.5 | G30: =ROUNDUP(G29/(1-F30),0) -> #N/A | H30: =G30/$L$10 -> #N/A | I30: /sft | L30: Top/Bottom | M30: =$M$10*2 -> 2 | N30: =$N$10 -> 1 | O30: 0 | P30: =$P$10 -> 1.3 | Q30: =M30*N30*P30 -> 2.6
B31: INC GST | F31: 0.18 | G31: =ROUNDUP(G30*(1+F31),0) -> #N/A | H31: =G31/$L$10 -> #N/A | I31: /sft | L31: Partition | M31: =S10*2 -> 2 | N31: 0 | O31: =$O$10 -> 1.2 | P31: =$P$10 -> 1.3 | Q31: =M31*O31*P31 -> 3.12
B32: INC HANDELING FEE | F32: 0.08 | G32: =ROUNDUP(G31*(1+F32),0) -> #N/A | H32: =G32/$L$10 -> #N/A | I32: /sft | L32: shelves | M32: =R10*2 -> 0 | N32: =$N$10 -> 1 | O32: 0 | P32: =$P$10 -> 1.3 | Q32: =M32*N32*P32 -> 0
L33: Drawers | M33: =T10 -> 1 | N33: =$S$11 -> 6 | O33: =$T$11 -> 0.5 | P33: =$U$11 -> 0.6
L34: Base | M34: =M20*2 -> 2 | N34: =$N$19 -> 6 | O34: 0 | P34: =$P$19 -> 0.6 | Q34: =M34*N34*P34 -> 7.2
L35: Sides | M35: =M21*2 -> 4 | N35: 0 | O35: =$O$19 -> 0.5 | P35: =$P$19 -> 0.6 | Q35: =M35*O35*P35 -> 1.2
L36: Sides (F/B) | M36: =T10*3 -> 3 | N36: =$N$19 -> 6 | O36: =$O$19 -> 0.5 | P36: 0 | Q36: =M36*N36*O36 -> 9
Q37: =SUM(Q28:Q36) -> 28.64 | R37: SQM
O38: Total | Q38: =Q37*10.764 -> 308.28096 | R38: SFT
L39: External FINISH
L40: Front/Shutter &Back | M40: =$M$10*2 -> 2 | N40: =$N$10 -> 1 | O40: =$O$10 -> 1.2 | P40: 0 | Q40: =M40*N40*O40 -> 2.4
L41: Sides | M41: =$M$10*2 -> 2 | N41: 0 | O41: =$O$10 -> 1.2 | P41: =$P$10 -> 1.3 | Q41: =M41*O41*P41 -> 3.12
L42: Top/Bottom | M42: =$M$10*2 -> 2 | N42: =$N$10 -> 1 | O42: 0 | P42: =$P$10 -> 1.3 | Q42: =M42*N42*P42 -> 2.6
...

Sheet STORAGE - 
A1: MATERIAL CALCULATION | K1: BILL OF MATERIALS (Per Unit)
A2: Area | B2: =upper(B6) -> NOS | C2: LENGTH | D2: HEIGHT | E2: DEPTH | G2: =upper(A12) -> SHELVES | H2: PARTITION | I2: DRAWERS | J2: SHUTTERS
A3: =roundup(C3*D3*10.764 , 0) -> 26 | B3: 1 | C3: 2 | D3: 1.2 | E3: 0.6 | G3: 0 | H3: 0 | I3: 0 | J3: 0
H4: 0.4 | I4: 0.225 | J4: =E3 -> 0.6
B6: Nos | C6: L | D6: H | E6: D | F6: Quantity | K6: Sl NO | L6: CATEGORY | M6: ITEM | N6: UOM | O6: QUANTITY | P6: RATE | Q6: AMOUNT
A7: BASE MATERIAL
A8: Front/Shutter &Back | B8: =$B$3*2 -> 2 | C8: =$C$3 -> 2 | D8: =$D$3 -> 1.2 | E8: 0 | F8: =B8*C8*D8 -> 4.8 | I8: B M | J8: =F18*1.1 -> 102.30106 | K8: 1 | L8: =A7 -> BASE MATERIAL | M8: ply MR - 18mm | N8: NOS | O8: =roundup(J8/32,0) -> 4 | P8: =vlookup(M8,Master!$C$5:$H$110,6,0) -> 2336 | Q8: =P8*O8 -> 9344
A9: Sides | B9: =$B$3*2 -> 2 | C9: 0 | D9: =D3 -> 1.2 | E9: =$E$3 -> 0.6 | F9: =B9*D9*E9 -> 1.44 | I9: I F | J9: =F32*1.1 -> 102.30106 | K9: 2 | L9: =A21 -> INTERNAL FINISH | M9: 0.8mm white | N9: NOS | O9: =roundup(J9/32,0) -> 4 | P9: =vlookup(M9,Master!$C$5:$H$110,6,0) -> #N/A | Q9: =P9*O9 -> #N/A
A10: Top/Bottom | B10: =$B$3*2 -> 2 | C10: =$C$3 -> 2 | D10: 0 | E10: =$E$3 -> 0.6 | F10: =B10*C10*E10 -> 2.4 | I10: E F | J10: =F44*1.1 -> 102.30106 | K10: 3 | L10: =A33 -> External FINISH | M10: Sf laminate | N10: NOS | O10: =roundup(J10/32,0) -> 4 | P10: =vlookup(M10,Master!$C$5:$H$110,6,0) -> 1500 | Q10: =P10*O10 -> 6000
A11: Partition | B11: =$H$3 -> 0 | C11: 0 | D11: =$D$3 -> 1.2 | E11: =$E$3 -> 0.6 | F11: =B11*D11*E11 -> 0 | K11: 4 | L11: Fevicol (SH+SR) | M11: Fevicol (SH+SR) | N11: KG | O11: =O8 -> 4 | P11: =vlookup(M11,Master!$C$5:$H$110,6,0) -> 245 | Q11: =P11*O11 -> 980
A12: shelves | B12: =$G$3 -> 0 | C12: =$C$3 -> 2 | D12: 0 | E12: =$E$3 -> 0.6 | F12: =B12*C12*E12 -> 0 | K12: 5 | L12: Handle /Knob | M12: Handle | N12: NOS | O12: =J3 -> 0 | P12: =vlookup(M12,Master!$C$5:$H$110,6,0) -> 200 | Q12: =P12*O12 -> 0
A13: Drawers | B13: =I3 -> 0 | C13: =H4 -> 0.4 | D13: =I4 -> 0.225 | E13: =J4 -> 0.6 | K13: 6 | L13: Hinges | M13: Ebco-Non soft | N13: PAIRS | O13: =J3 -> 0 | P13: =vlookup(M13,Master!$C$5:$H$110,6,0) -> 100 | Q13: =P13*O13 -> 0
A14: Base | B14: =I3 -> 0 | C14: =$C$13 -> 0.4 | D14: 0 | E14: =$E$13 -> 0.6 | F14: =B14*C14*E14 -> 0 | K14: 7 | L14: Channels for drawers | M14: Hetich -Soft | N14: PAIRS | O14: =I3 -> 0 | P14: =vlookup(M14,Master!$C$5:$H$110,6,0) -> #N/A | Q14: =P14*O14 -> #N/A
A15: Sides | B15: =I3*2 -> 0 | C15: 0 | D15: =$D$13 -> 0.225 | E15: =$E$13 -> 0.6 | F15: =B15*D15*E15 -> 0 | K15: 8 | L15: lock | M15: Epco Locks | N15: NOS | O15: 0 | P15: =vlookup(M15,Master!$C$5:$H$110,6,0) -> 174 | Q15: =P15*O15 -> 0
A16: Sides (F/B) | B16: =I3*2 -> 0 | C16: =$C$13 -> 0.4 | D16: =$D$13 -> 0.225 | E16: 0 | F16: =B16*C16*D16 -> 0 | K16: 9 | L16: Nails | M16: Nails | N16: KG | O16: =A3*0.15 -> 3.9 | P16: =vlookup(M16,Master!$C$5:$H$110,6,0) -> 80 | Q16: =P16*O16 -> 312
F17: =SUM(F8:F16) -> 8.64 | G17: SQM | K17: 10 | L17: jaali | M17: Jaali(12mm MDF ) | N17: SFT | O17: 0 | P17: =vlookup(M17,Master!$C$5:$H$110,6,0) -> #N/A | Q17: =P17*O17 -> #N/A
D18: Total | F18: =F17*10.764 -> 93.00096 | G18: SFT | K18: 11 | L18: Additional | M18: 6mm Clear Glass | N18: SFT | O18: 0 | P18: =vlookup(M18,Master!C111:H143,6) -> #N/A | Q18: =(ifs(O18=0,0,O18>=1,(O18*P18))) -> 0
K19: 12 | M19: Mirror | N19: SFT | O19: 0 | P19: =vlookup(M19,Master!C112:H144,6) -> 150 | Q19: =P19*O19 -> 0
A20: FINISHING MATERIAL | K20: 13 | M20: 8mm Extra Clear Glass | N20: SFT | O20: 0 | P20: =vlookup(M20,Master!C113:H145,6) -> 150 | Q20: =P20*O20 -> 0
A21: INTERNAL FINISH | K21: 14 | L21: Miscellaneous item | M21: 0.05 | N21: LS | O21: 1 | P21: =(sum(Q8:Q10)*M21) -> #N/A | Q21: =P21*O21 -> #N/A
A22: Front/Shutter &Back | B22: =$B$3*2 -> 2 | C22: =$C$3 -> 2 | D22: =$D$3 -> 1.2 | E22: 0 | F22: =B22*C22*D22 -> 4.8 | K22: 15 | L22: Labour | M22: storage | N22: SFT | O22: =A3 -> 26 | P22: =vlookup(M22,Master!L77:N82,5,0) -> #REF! | Q22: =P22*O22 -> #REF!
A23: Sides | B23: =$B$3*2 -> 2 | C23: 0 | D23: =$D$3 -> 1.2 | E23: =$E$3 -> 0.6 | F23: =B23*D23*E23 -> 1.44 | K23: 16 | L23: Transportation | P23: 0.05 | Q23: =SUM(Q8:Q22)*P23 -> #N/A
A24: Top/Bottom | B24: =$B$3*2 -> 2 | C24: =$C$3 -> 2 | D24: 0 | E24: =$E$3 -> 0.6 | F24: =B24*C24*E24 -> 2.4 | L24: Total (COGS) | Q24: =SUM(Q8:Q23) -> #N/A | R24: =Q24/$A$3 -> #N/A | S24: /sft
A25: Partition | B25: =H3*2 -> 0 | C25: 0 | D25: =$D$3 -> 1.2 | E25: =$E$3 -> 0.6 | F25: =B25*D25*E25 -> 0 | L25: GRAND TOTAL | P25: 0.5 | Q25: =ROUNDUP(Q24/(1-P25),0) -> #N/A | R25: =Q25/$A$3 -> #N/A | S25: /sft
A26: shelves | B26: =G3*2 -> 0 | C26: =$C$3 -> 2 | D26: 0 | E26: =$E$3 -> 0.6 | F26: =B26*C26*E26 -> 0 | L26: INC GST | P26: 0.18 | Q26: =ROUNDUP(Q25*(1+P26),0) -> #N/A | R26: =Q26/$A$3 -> #N/A | S26: /sft
A27: Drawers | B27: =I3 -> 0 | C27: =$H$4 -> 0.4 | D27: =$I$4 -> 0.225 | E27: =$J$4 -> 0.6 | L27: INC HANDELING FEE | P27: 0.08 | Q27: =ROUNDUP(Q26*(1+P27),0) -> #N/A | R27: =Q27/$A$3 -> #N/A | S27: /sft
A28: Base | B28: =B14*2 -> 0 | C28: =$C$13 -> 0.4 | D28: 0 | E28: =$E$13 -> 0.6 | F28: =B28*C28*E28 -> 0 | R28: =R27/R24 -> #N/A
A29: Sides | B29: =B15*2 -> 0 | C29: 0 | D29: =$D$13 -> 0.225 | E29: =$E$13 -> 0.6 | F29: =B29*D29*E29 -> 0
A30: Sides (F/B) | B30: =I3*3 -> 0 | C30: =$C$13 -> 0.4 | D30: =$D$13 -> 0.225 | E30: 0 | F30: =B30*C30*D30 -> 0
F31: =SUM(F22:F30) -> 8.64 | G31: SQM
D32: Total | F32: =F31*10.764 -> 93.00096 | G32: SFT
A33: External FINISH
A34: Front/Shutter &Back | B34: =$B$3*2 -> 2 | C34: =$C$3 -> 2 | D34: =$D$3 -> 1.2 | E34: 0 | F34: =B34*C34*D34 -> 4.8
A35: Sides | B35: =$B$3*2 -> 2 | C35: 0 | D35: =$D$3 -> 1.2 | E35: =$E$3 -> 0.6 | F35: =B35*D35*E35 -> 1.44
A36: Top/Bottom | B36: =$B$3*2 -> 2 | C36: =$C$3 -> 2 | D36: 0 | E36: =$E$3 -> 0.6 | F36: =B36*C36*E36 -> 2.4
A37: Partition | B37: 0 | C37: 0 | D37: =$D$3 -> 1.2 | E37: =$E$3 -> 0.6 | F37: =B37*D37*E37 -> 0
A38: shelves | B38: 0 | C38: =$C$3 -> 2 | D38: 0 | E38: =$E$3 -> 0.6 | F38: =B38*C38*E38 -> 0
A39: Drawers | B39: =I3 -> 0 | C39: =$H$4 -> 0.4 | D39: =$I$4 -> 0.225 | E39: =$J$4 -> 0.6
A40: Base | B40: 0 | C40: =$C$13 -> 0.4 | D40: 0 | E40: =$E$13 -> 0.6 | F40: =B40*C40*E40 -> 0
A41: Sides | B41: 0 | C41: 0 | D41: =$D$13 -> 0.225 | E41: =$E$13 -> 0.6 | F41: =B41*D41*E41 -> 0
...

Sheet  STORAGE - OPEN -old 
K1: BILL OF MATERIALS (Per Unit)
A2: Area | B2: =upper(B6) -> NOS | C2: LENGTH | D2: HEIGHT | E2: DEPTH | G2: =upper(A12) -> SHELVES | H2: PARTITION
A3: =roundup(C3*D3*10.764 , 0) -> 13 | B3: 1 | C3: 1 | D3: 1.2 | E3: 0.6 | G3: 1 | H3: 1
B6: Nos | C6: L | D6: H | E6: D | F6: Quantity | K6: Sl NO | L6: CATEGORY | M6: ITEM | N6: UOM | O6: QUANTITY | P6: RATE | Q6: AMOUNT
A7: BASE MATERIAL
A8: Back panel | B8: 1 | C8: =$C$3 -> 1 | D8: =$D$3 -> 1.2 | E8: 0 | F8: =B8*C8*D8 -> 1.2 | I8: B M | J8: =F14*1.1 -> 61.096464 | K8: 1 | L8: =A7 -> BASE MATERIAL | M8: MDF -18mm | N8: NOS | O8: =roundup(J8/32,0) -> 2 | P8: =vlookup(M8,Master!$C$5:$H$110,6,0) -> #N/A | Q8: =P8*O8 -> #N/A
A9: Sides | B9: =$B$3*2 -> 2 | C9: 0 | D9: =D3 -> 1.2 | E9: =$E$3 -> 0.6 | F9: =B9*D9*E9 -> 1.44 | I9: F | J9: =F23*1.1 -> 122.19293 | K9: 2 | L9: =A16 -> FINISHING MATERIAL | M9: Sf laminate | N9: NOS | O9: =roundup(J9/32,0) -> 4 | P9: =vlookup(M9,Master!$C$5:$H$110,6,0) -> 1500 | Q9: =P9*O9 -> 6000
A10: Top/Bottom | B10: =$B$3*2 -> 2 | C10: =$C$3 -> 1 | D10: 0 | E10: =$E$3 -> 0.6 | F10: =B10*C10*E10 -> 1.2 | K10: 3 | L10: Fevicol (SH+SR) | M10: Fevicol (SH+SR) | N10: KG | O10: =O8 -> 2 | P10: =vlookup(M10,Master!$C$5:$H$110,6,0) -> 245 | Q10: =P10*O10 -> 490
A11: Partition | B11: =$H$3 -> 1 | C11: 0 | D11: =$D$3 -> 1.2 | E11: =$E$3 -> 0.6 | F11: =B11*D11*E11 -> 0.72 | K11: 4 | L11: Nails | M11: Nails | N11: KG | O11: =A3*0.15 -> 1.95 | P11: =vlookup(M11,Master!$C$5:$H$110,6,0) -> 80 | Q11: =P11*O11 -> 156
A12: shelves | B12: =$G$3 -> 1 | C12: =$C$3 -> 1 | D12: 0 | E12: =$E$3 -> 0.6 | F12: =B12*C12*E12 -> 0.6 | K12: 5 | L12: jaali | M12: Jaali(12mm MDF ) | N12: SFT | O12: 0 | P12: =vlookup(M12,Master!$C$5:$H$110,6,0) -> #N/A | Q12: =P12*O12 -> #N/A
F13: =SUM(F8:F12) -> 5.16 | G13: SQM | K13: 6 | L13: Additional | M13: 6mm Clear Glass | N13: SFT | O13: 0 | P13: =vlookup(M13,Master!C111:H143,6) -> #N/A | Q13: =(ifs(O13=0,0,O13>=1,(O13*P13))) -> 0
D14: Total | F14: =F13*10.764 -> 55.54224 | G14: SFT | K14: 7 | M14: 10mm Clear Glass | N14: SFT | O14: 0 | P14: =vlookup(M14,Master!C112:H144,6) -> #N/A | Q14: =P14*O14 -> #N/A
K15: 8 | M15: Mirror | N15: SFT | O15: 0 | P15: =vlookup(M15,Master!C113:H145,6) -> 150 | Q15: =P15*O15 -> 0
A16: FINISHING MATERIAL | K16: 9 | L16: Miscellaneous item | M16: 0.05 | N16: LS | O16: 1 | P16: =(sum(Q8:Q10)*M16) -> #N/A | Q16: =P16*O16 -> #N/A
A17: Back panel | B17: =B8*2 -> 2 | C17: =$C$3 -> 1 | D17: =$D$3 -> 1.2 | E17: 0 | F17: =B17*C17*D17 -> 2.4 | K17: 10 | L17: Labour | M17: open storage | N17: SFT | O17: =A3 -> 13 | P17: =vlookup(M17,Master!L77:N82,5,0) -> #REF! | Q17: =P17*O17 -> #REF!
A18: Sides | B18: =B9*2 -> 4 | C18: 0 | D18: =$D$3 -> 1.2 | E18: =$E$3 -> 0.6 | F18: =B18*D18*E18 -> 2.88 | K18: 11 | L18: Transportation | P18: 0.05 | Q18: =SUM(Q8:Q17)*P18 -> #N/A
A19: Top/Bottom | B19: =B10*2 -> 4 | C19: =$C$3 -> 1 | D19: 0 | E19: =$E$3 -> 0.6 | F19: =B19*C19*E19 -> 2.4 | L19: Total (COGS) | Q19: =SUM(Q8:Q18) -> #N/A | R19: =Q19/$A$3 -> #N/A | S19: /sft
A20: Partition | B20: =H3*2 -> 2 | C20: 0 | D20: =$D$3 -> 1.2 | E20: =$E$3 -> 0.6 | F20: =B20*D20*E20 -> 1.44 | L20: GRAND TOTAL | P20: 0.45 | Q20: =ROUNDUP(Q19/(1-P20),0) -> #N/A | R20: =Q20/$A$3 -> #N/A | S20: /sft
A21: shelves | B21: =G3*2 -> 2 | C21: =$C$3 -> 1 | D21: 0 | E21: =$E$3 -> 0.6 | F21: =B21*C21*E21 -> 1.2 | L21: INC GST | P21: 0.18 | Q21: =ROUNDUP(Q20*(1+P21),0) -> #N/A | R21: =Q21/$A$3 -> #N/A | S21: /sft
F22: =SUM(F17:F21) -> 10.32 | G22: SQM | L22: INC HANDELING FEE | P22: 0.08 | Q22: =ROUNDUP(Q21*(1+P22),0) -> #N/A | R22: =Q22/$A$3 -> #N/A | S22: /sft
D23: Total | F23: =F22*10.764 -> 111.08448 | G23: SFT
